# Task Workflow Fix Summary

## Issue Description

You were experiencing an error where the API response showed:
```json
{
  "task_id": "b144b4fc-77a5-4802-b004-eb4b023c728a",
  "agent_id": "8a71cad0-0e9a-4b9e-9106-db9bc87e709e", 
  "error": "Task failed to start workflow",
  "status": "submitted",
  "result": null,
  "timestamp": "2025-08-05T17:55:19.236135+00:00"
}
```

However, you mentioned that **the task actually runs in the workflow**, which indicated a disconnect between the task status and the actual workflow execution.

## Root Cause Analysis

After thorough investigation using diagnostic scripts, we identified the exact root cause:

### The Problem

1. **TemporalTaskManager.submit_task()** successfully starts the Temporal workflow
2. The workflow runs correctly (as you observed)
3. But the task status was set to `"submitted"` instead of `"running"`
4. The API endpoint in `agents_tasks.py` has this logic:
   ```python
   has_execution_id = task.execution_id is not None
   status_running_or_pending = task.status in ["running", "pending"]
   
   if has_execution_id and status_running_or_pending:
       # Stream events (SUCCESS)
   else:
       # Show "Task failed to start workflow" (FAILURE)
   ```
5. Since `task.status = "submitted"` (not in `["running", "pending"]`), the API showed the error

### The Disconnect

- **Workflow Status**: `RUNNING` ✅ (working correctly)
- **Task Status**: `"submitted"` ❌ (should be `"running"`)
- **API Logic**: Requires both `execution_id` AND status in `["running", "pending"]`

## The Fix

### File Changed
`core/libs/tasks/agentarea_tasks/temporal_task_manager.py`

### What Was Changed

In the `submit_task()` method (around line 130), we changed:

**BEFORE (Broken):**
```python
await self.temporal_executor.start_workflow(
    workflow_name="AgentExecutionWorkflow",
    workflow_id=workflow_id,
    args=args_dict,
    config=config
)

# Update task status to submitted
updated_task_domain = await self.task_repository.update_status(task.id, "submitted")
```

**AFTER (Fixed):**
```python
execution_id = await self.temporal_executor.start_workflow(
    workflow_name="AgentExecutionWorkflow",
    workflow_id=workflow_id,
    args=args_dict,
    config=config
)

# Update task status to running (not submitted) since workflow started successfully
# Also set the execution_id for tracking
updated_task_domain = await self.task_repository.update_status(task.id, "running")
if updated_task_domain:
    # Set execution_id on the task
    updated_task_domain.execution_id = execution_id
    updated_task_domain = await self.task_repository.update_task(updated_task_domain)
```

### Key Changes

1. **Capture `execution_id`**: Store the workflow execution ID returned by `start_workflow()`
2. **Set status to `"running"`**: Instead of `"submitted"`, use `"running"` since the workflow is actually running
3. **Store `execution_id`**: Properly set and persist the execution ID on the task

## Why This Fixes The Issue

### Before Fix
- Task status: `"submitted"` 
- API check: `"submitted"` not in `["running", "pending"]` → **FAIL**
- Result: "Task failed to start workflow" error

### After Fix  
- Task status: `"running"`
- API check: `"running"` in `["running", "pending"]` → **SUCCESS**
- Result: Events stream correctly, no error message

## Verification

The fix has been verified with comprehensive tests:

✅ **Fixed Task Status Test**: Confirms tasks now get `status="running"` and proper `execution_id`
✅ **API Endpoint Simulation**: Confirms API logic now works correctly
✅ **Workflow Execution**: Confirms workflows still start and run properly

## Expected Behavior After Fix

1. **Task Creation**: When you create a task, it will:
   - Start the Temporal workflow successfully
   - Set task status to `"running"` (not `"submitted"`)
   - Set the `execution_id` properly

2. **API Response**: Instead of the error, you'll get:
   ```json
   {
     "task_id": "...",
     "agent_id": "...",
     "status": "running",
     "execution_id": "task-...",
     "result": null,
     "timestamp": "..."
   }
   ```

3. **Event Streaming**: The API will stream task events correctly instead of showing the error

## Testing The Fix

### Manual Testing
1. Restart your application to load the updated code
2. Create a new task via the API
3. Verify you no longer see "Task failed to start workflow"
4. Verify the task streams events correctly

### Automated Testing
Run the verification script:
```bash
cd /Users/jamakase/Projects/startup/agentarea
python verify_task_fix.py
```

## Files Created During Investigation

- `smoke_test_task_creation.py` - Initial diagnostic script
- `debug_task_status_transitions.py` - Detailed root cause analysis
- `verify_task_fix.py` - Fix verification script
- `diagnostic_results.json` - Initial diagnostic results
- `debug_task_status_results.json` - Root cause analysis results  
- `task_fix_verification_results.json` - Fix verification results
- `TASK_WORKFLOW_FIX_SUMMARY.md` - This summary document

## Summary

The "Task failed to start workflow" error was **not** because workflows weren't starting (they were running correctly), but because of a **status mismatch** between the task record and the actual workflow state. The fix ensures that when a workflow starts successfully, the task status correctly reflects this by being set to `"running"` instead of `"submitted"`.

This was a classic case where the underlying system (Temporal workflows) was working correctly, but the application state tracking was inconsistent, leading to confusing error messages in the API.